<?xml version="1.0" encoding="utf-8"?>
<!-- AlohaMini with official ManiSkill SO100 Arms -->
<!-- Base structure from aloha_mini_virtual_base.urdf -->
<!-- Arms from ManiSkill so100.urdf with left_/right_ prefixes -->
<robot name="aloha_mini_maniskill_so100">

  <material name="white">
    <color rgba="0.95 0.95 0.95 1" />
  </material>
  <material name="motor">
    <color rgba="0.05 0.05 0.05 1" />
  </material>

  <!-- Virtual Base Links (zero mass) for mobile base simulation -->
  <link name="root">
    <inertial>
      <mass value="0"/>
      <inertia ixx="0.00" ixy="0.00" ixz="0.00" iyy="0.00" iyz="0.00" izz="0.00"/>
    </inertial>
  </link>

  <link name="root_x_link">
    <inertial>
      <mass value="0"/>
      <inertia ixx="0.00" ixy="0.00" ixz="0.00" iyy="0.00" iyz="0.00" izz="0.00"/>
    </inertial>
  </link>

  <link name="root_y_link">
    <inertial>
      <mass value="0"/>
      <inertia ixx="0.00" ixy="0.00" ixz="0.00" iyy="0.00" iyz="0.00" izz="0.00"/>
    </inertial>
  </link>

  <!-- Virtual Base Joints -->
  <joint name="root_x_axis_joint" type="prismatic">
    <parent link="root"/>
    <child link="root_x_link"/>
    <axis xyz="1 0 0"/>
    <limit effort="500" lower="-20" upper="20" velocity="1.0"/>
    <dynamics damping="100.0" friction="10"/>
  </joint>

  <joint name="root_y_axis_joint" type="prismatic">
    <parent link="root_x_link"/>
    <child link="root_y_link"/>
    <axis xyz="0 1 0"/>
    <limit effort="500" lower="-20" upper="20" velocity="1.0"/>
    <dynamics damping="100.0" friction="10"/>
  </joint>

  <joint name="root_z_rotation_joint" type="continuous">
    <parent link="root_y_link"/>
    <child link="base_link"/>
    <axis xyz="0 0 1"/>
    <dynamics damping="100.0" friction="10"/>
  </joint>

  <!-- Physical Base Link -->
  <link name="base_link">
    <inertial>
      <origin xyz="-0.00084648 0.00978917 0.34475333" rpy="0 0 0" />
      <mass value="5.09802085" />
      <inertia ixx="0.02139147" ixy="-9.32122e-05" ixz="2.18297e-05"
               iyy="0.02009437" iyz="-0.00021314" izz="0.02209675" />
    </inertial>
    <visual>
      <origin xyz="0 0 0" rpy="0 0 0" />
      <geometry>
        <mesh filename="meshes/base_link.STL" />
      </geometry>
      <material name="white" />
    </visual>
    <collision>
      <origin xyz="0 0 0" rpy="0 0 0" />
      <geometry>
        <mesh filename="meshes/base_link.STL" />
      </geometry>
    </collision>
  </link>

  <!-- Wheels (visual only) -->
  <link name="wheel1">
    <inertial>
      <origin xyz="-5.2749e-05 0.01577411 -1.8443e-07" rpy="0 0 0" />
      <mass value="0.19481896" />
      <inertia ixx="5.0889e-05" ixy="3.6052e-11" ixz="2.6907e-11"
               iyy="9.3635e-05" iyz="-4.4529e-12" izz="5.089e-05" />
    </inertial>
    <visual>
      <origin xyz="0 0 0" rpy="0 0 0" />
      <geometry>
        <mesh filename="meshes/wheel1.STL" />
      </geometry>
      <material name="white" />
    </visual>
  </link>
  <joint name="wheel1_joint" type="fixed">
    <origin xyz="-0.1538 0.091161 0.0422" rpy="0 0 -2.1099" />
    <parent link="base_link" />
    <child link="wheel1" />
  </joint>

  <link name="wheel2">
    <inertial>
      <origin xyz="-6.4495e-06 0.01577407 -5.2356e-05" rpy="0 0 0" />
      <mass value="0.19481804" />
      <inertia ixx="5.089e-05" ixy="-1.2087e-12" ixz="-2.0278e-10"
               iyy="9.3635e-05" iyz="5.3546e-11" izz="5.0889e-05" />
    </inertial>
    <visual>
      <origin xyz="0 0 0" rpy="0 0 0" />
      <geometry>
        <mesh filename="meshes/wheel2.STL" />
      </geometry>
      <material name="white" />
    </visual>
  </link>
  <joint name="wheel2_joint" type="fixed">
    <origin xyz="0.15563 0.087993 0.0422" rpy="0 0 2.086" />
    <parent link="base_link" />
    <child link="wheel2" />
  </joint>

  <link name="wheel3">
    <inertial>
      <origin xyz="0.00021759 0.01577265 -4.564e-05" rpy="0 0 0" />
      <mass value="0.19481853" />
      <inertia ixx="5.09e-05" ixy="6.6162e-07" ixz="-7.5485e-10"
               iyy="9.3625e-05" iyz="7.6853e-11" izz="5.089e-05" />
    </inertial>
    <visual>
      <origin xyz="0 0 0" rpy="0 0 0" />
      <geometry>
        <mesh filename="meshes/wheel3.STL" />
      </geometry>
      <material name="white" />
    </visual>
  </link>
  <joint name="wheel3_joint" type="fixed">
    <origin xyz="-0.0020354 -0.17875 0.0422" rpy="0 0 0" />
    <parent link="base_link" />
    <child link="wheel3" />
  </joint>

  <!-- Vertical Link (Lift) -->
  <link name="vertical_link">
    <inertial>
      <origin xyz="-0.00028187 0.00785824 0.63016724" rpy="0 0 0" />
      <mass value="1.13349901" />
      <inertia ixx="0.00108584" ixy="2.1331e-05" ixz="-1.0049e-05"
               iyy="0.00311025" iyz="-2.9641e-05" izz="0.00240766" />
    </inertial>
    <visual>
      <origin xyz="0 0 0" rpy="0 0 0" />
      <geometry>
        <mesh filename="meshes/vertical_link.STL" />
      </geometry>
      <material name="white" />
    </visual>
    <collision>
      <origin xyz="0 0 0" rpy="0 0 0" />
      <geometry>
        <mesh filename="meshes/vertical_link.STL" />
      </geometry>
    </collision>
  </link>
  <joint name="vertical_move" type="prismatic">
    <origin xyz="-0.001045 -0.067891 0.064" rpy="0 0 0" />
    <parent link="base_link" />
    <child link="vertical_link" />
    <axis xyz="0 0 1" />
    <limit lower="-0.15" upper="0.6" effort="100" velocity="0.5" />
  </joint>

  <!-- ========== LEFT ARM (Official ManiSkill SO100) ========== -->
  <!-- Position: positive X (like aloha_mini_virtual_base.urdf) -->
  <link name="left_Base">
    <inertial>
      <origin xyz="-2.45960666746703E-07 0.0311418169687909 0.0175746661003382" rpy="0 0 0" />
      <mass value="0.193184127927598" />
      <inertia ixx="0.000137030709467877" ixy="2.10136126944992E-08" ixz="4.24087422551286E-09"
               iyy="0.000169089551209259" iyz="2.26514711036514E-05" izz="0.000145097720857224" />
    </inertial>
    <visual name="left_base_link_chassis">
      <origin xyz="0 0 0" rpy="0 0 0" />
      <geometry>
        <mesh filename="so100_meshes/Base.stl" />
      </geometry>
      <material name="white" />
    </visual>
    <visual name="left_base_link_motor">
      <origin xyz="0 0 0" rpy="0 0 0" />
      <geometry>
        <mesh filename="so100_meshes/Base_Motor.stl" />
      </geometry>
      <material name="motor" />
    </visual>
    <collision>
      <origin xyz="0 0 0" rpy="0 0 0" />
      <geometry>
        <mesh filename="so100_meshes/Base.stl" />
      </geometry>
    </collision>
  </link>

  <!-- Left arm base joint: NO rotation, position only -->
  <joint name="left_base_joint" type="fixed">
    <origin xyz="0.15726 0.026474 0.68821" rpy="0 0 0" />
    <parent link="vertical_link" />
    <child link="left_Base" />
  </joint>

  <link name="left_Rotation_Pitch">
    <inertial>
      <origin xyz="-9.07886224712597E-05 0.0590971820568318 0.031089016892169" rpy="0 0 0" />
      <mass value="0.119226314127197" />
      <inertia ixx="5.90408775624429E-05" ixy="4.90800532852998E-07" ixz="-5.90451772654387E-08"
               iyy="3.21498601038881E-05" iyz="-4.58026206663885E-06" izz="5.86058514263952E-05" />
    </inertial>
    <visual name="left_rotation_pitch_chassis">
      <origin xyz="0 0 0" rpy="0 0 0" />
      <geometry>
        <mesh filename="so100_meshes/Rotation_Pitch.stl" />
      </geometry>
      <material name="white" />
    </visual>
    <visual name="left_rotation_pitch_motor">
      <origin xyz="0 0 0" rpy="0 0 0" />
      <geometry>
        <mesh filename="so100_meshes/Rotation_Pitch_Motor.stl" />
      </geometry>
      <material name="motor" />
    </visual>
    <collision>
      <origin xyz="0 0 0" rpy="0 0 0" />
      <geometry>
        <mesh filename="so100_meshes/Rotation_Pitch.stl" />
      </geometry>
    </collision>
  </link>

  <!-- Left shoulder_pan: official ManiSkill SO100 rotation -->
  <joint name="left_shoulder_pan" type="revolute">
    <origin xyz="0 -0.0452 0.0165" rpy="1.5708 0 0" />
    <parent link="left_Base" />
    <child link="left_Rotation_Pitch" />
    <axis xyz="0 -1 0" />
    <limit lower="-2.0" upper="2.0" effort="0" velocity="0" />
  </joint>

  <link name="left_Upper_Arm">
    <inertial>
      <origin xyz="-1.7205170190925E-05 0.0701802156327694 0.00310545118155671" rpy="0 0 0" />
      <mass value="0.162409284599177" />
      <inertia ixx="0.000167153146617081" ixy="1.03902689187701E-06" ixz="-1.20161820645189E-08"
               iyy="7.01946992214245E-05" iyz="2.11884806298698E-06" izz="0.000213280241160769" />
    </inertial>
    <visual name="left_upper_arm_chassis">
      <origin xyz="0 0 0" rpy="0 0 0" />
      <geometry>
        <mesh filename="so100_meshes/Upper_Arm.stl" />
      </geometry>
      <material name="white" />
    </visual>
    <visual name="left_upper_arm_motor">
      <origin xyz="0 0 0" rpy="0 0 0" />
      <geometry>
        <mesh filename="so100_meshes/Upper_Arm_Motor.stl" />
      </geometry>
      <material name="motor" />
    </visual>
    <collision>
      <origin xyz="0 0 0" rpy="0 0 0" />
      <geometry>
        <mesh filename="so100_meshes/Upper_Arm.stl" />
      </geometry>
    </collision>
  </link>

  <joint name="left_shoulder_lift" type="revolute">
    <origin xyz="0 0.1025 0.0306" rpy="0 0 0" />
    <parent link="left_Rotation_Pitch" />
    <child link="left_Upper_Arm" />
    <axis xyz="1 0 0" />
    <limit lower="-1.5708" upper="1.5708" effort="0" velocity="0" />
  </joint>

  <link name="left_Lower_Arm">
    <inertial>
      <origin xyz="-0.00339603710186651 0.00137796353960074 0.0768006751156044" rpy="0 0 0" />
      <mass value="0.147967774582291" />
      <inertia ixx="0.000105333995841409" ixy="1.73059237226499E-07" ixz="-1.1720305455211E-05"
               iyy="0.000138766654485212" iyz="1.77429964684103E-06" izz="5.08741652515214E-05" />
    </inertial>
    <visual name="left_lower_arm_chassis">
      <origin xyz="0 0 0" rpy="0 0 0" />
      <geometry>
        <mesh filename="so100_meshes/Lower_Arm.stl" />
      </geometry>
      <material name="white" />
    </visual>
    <visual name="left_lower_arm_motor">
      <origin xyz="0 0 0" rpy="0 0 0" />
      <geometry>
        <mesh filename="so100_meshes/Lower_Arm_Motor.stl" />
      </geometry>
      <material name="motor" />
    </visual>
    <collision>
      <origin xyz="0 0 0" rpy="0 0 0" />
      <geometry>
        <mesh filename="so100_meshes/Lower_Arm.stl" />
      </geometry>
    </collision>
  </link>

  <joint name="left_elbow_flex" type="revolute">
    <origin xyz="0 0.11257 0.028" rpy="0 0 0" />
    <parent link="left_Upper_Arm" />
    <child link="left_Lower_Arm" />
    <axis xyz="1 0 0" />
    <limit lower="-1.5708" upper="1.5708" effort="0" velocity="0" />
  </joint>

  <link name="left_Wrist_Pitch_Roll">
    <inertial>
      <origin xyz="-0.00852653127372418 -0.0352278997897927 -2.34622481569413E-05" rpy="0 0 0" />
      <mass value="0.066132067097723" />
      <inertia ixx="1.95717492443445E-05" ixy="-6.62714374412293E-07" ixz="5.20089016442066E-09"
               iyy="2.38028417569933E-05" iyz="4.09549055863776E-08" izz="3.4540143384536E-05" />
    </inertial>
    <visual name="left_wrist_pitch_roll_chassis">
      <origin xyz="0 0 0" rpy="0 0 0" />
      <geometry>
        <mesh filename="so100_meshes/Wrist_Pitch_Roll.stl" />
      </geometry>
      <material name="white" />
    </visual>
    <visual name="left_wrist_pitch_roll_motor">
      <origin xyz="0 0 0" rpy="0 0 0" />
      <geometry>
        <mesh filename="so100_meshes/Wrist_Pitch_Roll_Motor.stl" />
      </geometry>
      <material name="motor" />
    </visual>
    <collision>
      <origin xyz="0 0 0" rpy="0 0 0" />
      <geometry>
        <mesh filename="so100_meshes/Wrist_Pitch_Roll.stl" />
      </geometry>
    </collision>
  </link>

  <joint name="left_wrist_flex" type="revolute">
    <origin xyz="0 0.0052 0.1349" rpy="-1.5708 0 0" />
    <parent link="left_Lower_Arm" />
    <child link="left_Wrist_Pitch_Roll" />
    <axis xyz="1 0 0" />
    <limit lower="-1.8" upper="1.8" effort="0" velocity="0" />
  </joint>

  <link name="left_Fixed_Jaw">
    <inertial>
      <origin xyz="0.00552376906426563 -0.0280167153359021 0.000483582592841092" rpy="0 0 0" />
      <mass value="0.0929859131176897" />
      <inertia ixx="4.3328249304211E-05" ixy="7.09654328670947E-06" ixz="5.99838530879484E-07"
               iyy="3.04451747368212E-05" iyz="-1.58743247545413E-07" izz="5.02460913506734E-05" />
    </inertial>
    <visual name="left_fixed_jaw_chassis">
      <origin xyz="0 0 0" rpy="0 0 0" />
      <geometry>
        <mesh filename="so100_meshes/Fixed_Jaw.stl" />
      </geometry>
      <material name="white" />
    </visual>
    <visual name="left_fixed_jaw_motor">
      <origin xyz="0 0 0" rpy="0 0 0" />
      <geometry>
        <mesh filename="so100_meshes/Fixed_Jaw_Motor.stl" />
      </geometry>
      <material name="motor" />
    </visual>
    <collision>
      <origin xyz="0 0 0" rpy="0 0 0" />
      <geometry>
        <mesh filename="so100_meshes/Fixed_Jaw.stl" />
      </geometry>
    </collision>
  </link>

  <joint name="left_wrist_roll" type="revolute">
    <origin xyz="0 -0.0601 0" rpy="0 1.5708 0" />
    <parent link="left_Wrist_Pitch_Roll" />
    <child link="left_Fixed_Jaw" />
    <axis xyz="0 1 0" />
    <limit lower="-3.14159" upper="3.14159" effort="0" velocity="0" />
  </joint>

  <link name="left_Moving_Jaw">
    <inertial>
      <origin xyz="-0.00161744605468241 -0.0303472584046471 0.000449645961853651" rpy="0 0 0" />
      <mass value="0.0202443794940372" />
      <inertia ixx="1.10911325081525E-05" ixy="-5.35076503033314E-07" ixz="-9.46105662101403E-09"
               iyy="3.03576451001973E-06" iyz="-1.71146075110632E-07" izz="8.9916083370498E-06" />
    </inertial>
    <visual name="left_moving_jaw_chassis">
      <origin xyz="0 0 0" rpy="0 0 0" />
      <geometry>
        <mesh filename="so100_meshes/Moving_Jaw.stl" />
      </geometry>
      <material name="white" />
    </visual>
    <collision>
      <origin xyz="0 0 0" rpy="0 0 0" />
      <geometry>
        <mesh filename="so100_meshes/Moving_Jaw.stl" />
      </geometry>
    </collision>
  </link>

  <joint name="left_gripper" type="revolute">
    <origin xyz="-0.0202 -0.0244 0" rpy="0 3.14159 -0.9" />
    <parent link="left_Fixed_Jaw" />
    <child link="left_Moving_Jaw" />
    <axis xyz="0 0 1" />
    <limit lower="-1.1" upper="1.1" effort="0" velocity="0" />
  </joint>

  <!-- Left arm tip links -->
  <joint name="left_Fixed_Jaw_tip_joint" type="fixed">
    <origin rpy="0 0 0" xyz="0.01 -0.097 0"/>
    <parent link="left_Fixed_Jaw"/>
    <child link="left_Fixed_Jaw_tip"/>
  </joint>
  <link name="left_Fixed_Jaw_tip" />

  <joint name="left_Moving_Jaw_tip_joint" type="fixed">
    <origin rpy="0 0 0" xyz="-0.01 -0.073 0"/>
    <parent link="left_Moving_Jaw"/>
    <child link="left_Moving_Jaw_tip"/>
  </joint>
  <link name="left_Moving_Jaw_tip" />

  <!-- ========== RIGHT ARM (Official ManiSkill SO100) ========== -->
  <!-- Position: negative X (like aloha_mini_virtual_base.urdf) -->
  <link name="right_Base">
    <inertial>
      <origin xyz="-2.45960666746703E-07 0.0311418169687909 0.0175746661003382" rpy="0 0 0" />
      <mass value="0.193184127927598" />
      <inertia ixx="0.000137030709467877" ixy="2.10136126944992E-08" ixz="4.24087422551286E-09"
               iyy="0.000169089551209259" iyz="2.26514711036514E-05" izz="0.000145097720857224" />
    </inertial>
    <visual name="right_base_link_chassis">
      <origin xyz="0 0 0" rpy="0 0 0" />
      <geometry>
        <mesh filename="so100_meshes/Base.stl" />
      </geometry>
      <material name="white" />
    </visual>
    <visual name="right_base_link_motor">
      <origin xyz="0 0 0" rpy="0 0 0" />
      <geometry>
        <mesh filename="so100_meshes/Base_Motor.stl" />
      </geometry>
      <material name="motor" />
    </visual>
    <collision>
      <origin xyz="0 0 0" rpy="0 0 0" />
      <geometry>
        <mesh filename="so100_meshes/Base.stl" />
      </geometry>
    </collision>
  </link>

  <!-- Right arm base joint: NO rotation, position only -->
  <joint name="right_base_joint" type="fixed">
    <origin xyz="-0.15657564 0.03021825 0.68890773" rpy="0 0 0" />
    <parent link="vertical_link" />
    <child link="right_Base" />
  </joint>

  <link name="right_Rotation_Pitch">
    <inertial>
      <origin xyz="-9.07886224712597E-05 0.0590971820568318 0.031089016892169" rpy="0 0 0" />
      <mass value="0.119226314127197" />
      <inertia ixx="5.90408775624429E-05" ixy="4.90800532852998E-07" ixz="-5.90451772654387E-08"
               iyy="3.21498601038881E-05" iyz="-4.58026206663885E-06" izz="5.86058514263952E-05" />
    </inertial>
    <visual name="right_rotation_pitch_chassis">
      <origin xyz="0 0 0" rpy="0 0 0" />
      <geometry>
        <mesh filename="so100_meshes/Rotation_Pitch.stl" />
      </geometry>
      <material name="white" />
    </visual>
    <visual name="right_rotation_pitch_motor">
      <origin xyz="0 0 0" rpy="0 0 0" />
      <geometry>
        <mesh filename="so100_meshes/Rotation_Pitch_Motor.stl" />
      </geometry>
      <material name="motor" />
    </visual>
    <collision>
      <origin xyz="0 0 0" rpy="0 0 0" />
      <geometry>
        <mesh filename="so100_meshes/Rotation_Pitch.stl" />
      </geometry>
    </collision>
  </link>

  <!-- Right shoulder_pan: official ManiSkill SO100 rotation -->
  <joint name="right_shoulder_pan" type="revolute">
    <origin xyz="0 -0.0452 0.0165" rpy="1.5708 0 0" />
    <parent link="right_Base" />
    <child link="right_Rotation_Pitch" />
    <axis xyz="0 -1 0" />
    <limit lower="-2.0" upper="2.0" effort="0" velocity="0" />
  </joint>

  <link name="right_Upper_Arm">
    <inertial>
      <origin xyz="-1.7205170190925E-05 0.0701802156327694 0.00310545118155671" rpy="0 0 0" />
      <mass value="0.162409284599177" />
      <inertia ixx="0.000167153146617081" ixy="1.03902689187701E-06" ixz="-1.20161820645189E-08"
               iyy="7.01946992214245E-05" iyz="2.11884806298698E-06" izz="0.000213280241160769" />
    </inertial>
    <visual name="right_upper_arm_chassis">
      <origin xyz="0 0 0" rpy="0 0 0" />
      <geometry>
        <mesh filename="so100_meshes/Upper_Arm.stl" />
      </geometry>
      <material name="white" />
    </visual>
    <visual name="right_upper_arm_motor">
      <origin xyz="0 0 0" rpy="0 0 0" />
      <geometry>
        <mesh filename="so100_meshes/Upper_Arm_Motor.stl" />
      </geometry>
      <material name="motor" />
    </visual>
    <collision>
      <origin xyz="0 0 0" rpy="0 0 0" />
      <geometry>
        <mesh filename="so100_meshes/Upper_Arm.stl" />
      </geometry>
    </collision>
  </link>

  <joint name="right_shoulder_lift" type="revolute">
    <origin xyz="0 0.1025 0.0306" rpy="0 0 0" />
    <parent link="right_Rotation_Pitch" />
    <child link="right_Upper_Arm" />
    <axis xyz="1 0 0" />
    <limit lower="-1.5708" upper="1.5708" effort="0" velocity="0" />
  </joint>

  <link name="right_Lower_Arm">
    <inertial>
      <origin xyz="-0.00339603710186651 0.00137796353960074 0.0768006751156044" rpy="0 0 0" />
      <mass value="0.147967774582291" />
      <inertia ixx="0.000105333995841409" ixy="1.73059237226499E-07" ixz="-1.1720305455211E-05"
               iyy="0.000138766654485212" iyz="1.77429964684103E-06" izz="5.08741652515214E-05" />
    </inertial>
    <visual name="right_lower_arm_chassis">
      <origin xyz="0 0 0" rpy="0 0 0" />
      <geometry>
        <mesh filename="so100_meshes/Lower_Arm.stl" />
      </geometry>
      <material name="white" />
    </visual>
    <visual name="right_lower_arm_motor">
      <origin xyz="0 0 0" rpy="0 0 0" />
      <geometry>
        <mesh filename="so100_meshes/Lower_Arm_Motor.stl" />
      </geometry>
      <material name="motor" />
    </visual>
    <collision>
      <origin xyz="0 0 0" rpy="0 0 0" />
      <geometry>
        <mesh filename="so100_meshes/Lower_Arm.stl" />
      </geometry>
    </collision>
  </link>

  <joint name="right_elbow_flex" type="revolute">
    <origin xyz="0 0.11257 0.028" rpy="0 0 0" />
    <parent link="right_Upper_Arm" />
    <child link="right_Lower_Arm" />
    <axis xyz="1 0 0" />
    <limit lower="-1.5708" upper="1.5708" effort="0" velocity="0" />
  </joint>

  <link name="right_Wrist_Pitch_Roll">
    <inertial>
      <origin xyz="-0.00852653127372418 -0.0352278997897927 -2.34622481569413E-05" rpy="0 0 0" />
      <mass value="0.066132067097723" />
      <inertia ixx="1.95717492443445E-05" ixy="-6.62714374412293E-07" ixz="5.20089016442066E-09"
               iyy="2.38028417569933E-05" iyz="4.09549055863776E-08" izz="3.4540143384536E-05" />
    </inertial>
    <visual name="right_wrist_pitch_roll_chassis">
      <origin xyz="0 0 0" rpy="0 0 0" />
      <geometry>
        <mesh filename="so100_meshes/Wrist_Pitch_Roll.stl" />
      </geometry>
      <material name="white" />
    </visual>
    <visual name="right_wrist_pitch_roll_motor">
      <origin xyz="0 0 0" rpy="0 0 0" />
      <geometry>
        <mesh filename="so100_meshes/Wrist_Pitch_Roll_Motor.stl" />
      </geometry>
      <material name="motor" />
    </visual>
    <collision>
      <origin xyz="0 0 0" rpy="0 0 0" />
      <geometry>
        <mesh filename="so100_meshes/Wrist_Pitch_Roll.stl" />
      </geometry>
    </collision>
  </link>

  <joint name="right_wrist_flex" type="revolute">
    <origin xyz="0 0.0052 0.1349" rpy="-1.5708 0 0" />
    <parent link="right_Lower_Arm" />
    <child link="right_Wrist_Pitch_Roll" />
    <axis xyz="1 0 0" />
    <limit lower="-1.8" upper="1.8" effort="0" velocity="0" />
  </joint>

  <link name="right_Fixed_Jaw">
    <inertial>
      <origin xyz="0.00552376906426563 -0.0280167153359021 0.000483582592841092" rpy="0 0 0" />
      <mass value="0.0929859131176897" />
      <inertia ixx="4.3328249304211E-05" ixy="7.09654328670947E-06" ixz="5.99838530879484E-07"
               iyy="3.04451747368212E-05" iyz="-1.58743247545413E-07" izz="5.02460913506734E-05" />
    </inertial>
    <visual name="right_fixed_jaw_chassis">
      <origin xyz="0 0 0" rpy="0 0 0" />
      <geometry>
        <mesh filename="so100_meshes/Fixed_Jaw.stl" />
      </geometry>
      <material name="white" />
    </visual>
    <visual name="right_fixed_jaw_motor">
      <origin xyz="0 0 0" rpy="0 0 0" />
      <geometry>
        <mesh filename="so100_meshes/Fixed_Jaw_Motor.stl" />
      </geometry>
      <material name="motor" />
    </visual>
    <collision>
      <origin xyz="0 0 0" rpy="0 0 0" />
      <geometry>
        <mesh filename="so100_meshes/Fixed_Jaw.stl" />
      </geometry>
    </collision>
  </link>

  <joint name="right_wrist_roll" type="revolute">
    <origin xyz="0 -0.0601 0" rpy="0 1.5708 0" />
    <parent link="right_Wrist_Pitch_Roll" />
    <child link="right_Fixed_Jaw" />
    <axis xyz="0 1 0" />
    <limit lower="-3.14159" upper="3.14159" effort="0" velocity="0" />
  </joint>

  <link name="right_Moving_Jaw">
    <inertial>
      <origin xyz="-0.00161744605468241 -0.0303472584046471 0.000449645961853651" rpy="0 0 0" />
      <mass value="0.0202443794940372" />
      <inertia ixx="1.10911325081525E-05" ixy="-5.35076503033314E-07" ixz="-9.46105662101403E-09"
               iyy="3.03576451001973E-06" iyz="-1.71146075110632E-07" izz="8.9916083370498E-06" />
    </inertial>
    <visual name="right_moving_jaw_chassis">
      <origin xyz="0 0 0" rpy="0 0 0" />
      <geometry>
        <mesh filename="so100_meshes/Moving_Jaw.stl" />
      </geometry>
      <material name="white" />
    </visual>
    <collision>
      <origin xyz="0 0 0" rpy="0 0 0" />
      <geometry>
        <mesh filename="so100_meshes/Moving_Jaw.stl" />
      </geometry>
    </collision>
  </link>

  <joint name="right_gripper" type="revolute">
    <origin xyz="-0.0202 -0.0244 0" rpy="0 3.14159 -0.9" />
    <parent link="right_Fixed_Jaw" />
    <child link="right_Moving_Jaw" />
    <axis xyz="0 0 1" />
    <limit lower="-1.1" upper="1.1" effort="0" velocity="0" />
  </joint>

  <!-- Right arm tip links -->
  <joint name="right_Fixed_Jaw_tip_joint" type="fixed">
    <origin rpy="0 0 0" xyz="0.01 -0.097 0"/>
    <parent link="right_Fixed_Jaw"/>
    <child link="right_Fixed_Jaw_tip"/>
  </joint>
  <link name="right_Fixed_Jaw_tip" />

  <joint name="right_Moving_Jaw_tip_joint" type="fixed">
    <origin rpy="0 0 0" xyz="-0.01 -0.073 0"/>
    <parent link="right_Moving_Jaw"/>
    <child link="right_Moving_Jaw_tip"/>
  </joint>
  <link name="right_Moving_Jaw_tip" />

</robot>
